
2022-07-08 01:26:39,523 Downloading artifacts
Traceback (most recent call last):
  File "/home/imdadul/miniconda3/envs/mlflow-078471fef0a832ef964cce936e2dfe85f5b9fa0d/lib/python3.10/site-packages/pandas/core/indexes/base.py", line 3621, in get_loc
    return self._engine.get_loc(casted_key)
  File "pandas/_libs/index.pyx", line 136, in pandas._libs.index.IndexEngine.get_loc
  File "pandas/_libs/index.pyx", line 163, in pandas._libs.index.IndexEngine.get_loc
  File "pandas/_libs/hashtable_class_helper.pxi", line 5198, in pandas._libs.hashtable.PyObjectHashTable.get_item
  File "pandas/_libs/hashtable_class_helper.pxi", line 5206, in pandas._libs.hashtable.PyObjectHashTable.get_item
KeyError: 'price'
The above exception was the direct cause of the following exception:
Traceback (most recent call last):
  File "/home/imdadul/Project Folder/Deploying a Machine Learning Model on Heroku with FastAPI/src/slice_performance_check/run.py", line 73, in <module>
    go(args)
  File "/home/imdadul/Project Folder/Deploying a Machine Learning Model on Heroku with FastAPI/src/slice_performance_check/run.py", line 34, in go
    y_test = X_test.pop("price")
  File "/home/imdadul/miniconda3/envs/mlflow-078471fef0a832ef964cce936e2dfe85f5b9fa0d/lib/python3.10/site-packages/pandas/core/frame.py", line 5270, in pop
    return super().pop(item=item)
  File "/home/imdadul/miniconda3/envs/mlflow-078471fef0a832ef964cce936e2dfe85f5b9fa0d/lib/python3.10/site-packages/pandas/core/generic.py", line 865, in pop
    result = self[item]
  File "/home/imdadul/miniconda3/envs/mlflow-078471fef0a832ef964cce936e2dfe85f5b9fa0d/lib/python3.10/site-packages/pandas/core/frame.py", line 3505, in __getitem__
    indexer = self.columns.get_loc(key)
  File "/home/imdadul/miniconda3/envs/mlflow-078471fef0a832ef964cce936e2dfe85f5b9fa0d/lib/python3.10/site-packages/pandas/core/indexes/base.py", line 3623, in get_loc
    raise KeyError(key) from err
KeyError: 'price'