2022-07-04 14:01:06,742 INFO    MainThread:413719 [internal.py:wandb_internal():90] W&B internal server running at pid: 413719, started at: 2022-07-04 14:01:06.742712
2022-07-04 14:01:06,744 INFO    WriterThread:413719 [datastore.py:open_for_write():75] open: /home/imdadul/Project Folder/Deploying a Machine Learning Model on Heroku with FastAPI/src/upload/wandb/run-20220704_140106-3p5zra5f/run-3p5zra5f.wandb
2022-07-04 14:01:06,745 DEBUG   SenderThread:413719 [sender.py:send():235] send: header
2022-07-04 14:01:06,745 DEBUG   SenderThread:413719 [sender.py:send():235] send: run
2022-07-04 14:01:36,376 DEBUG   HandlerThread:413719 [handler.py:handle_request():141] handle_request: shutdown
2022-07-04 14:01:36,377 INFO    HandlerThread:413719 [handler.py:finish():806] shutting down handler
2022-07-04 14:01:36,756 INFO    WriterThread:413719 [datastore.py:close():279] close: /home/imdadul/Project Folder/Deploying a Machine Learning Model on Heroku with FastAPI/src/upload/wandb/run-20220704_140106-3p5zra5f/run-3p5zra5f.wandb
2022-07-04 14:01:40,581 ERROR   SenderThread:413719 [retry.py:__call__():126] Retry attempt failed:
Traceback (most recent call last):
  File "/home/imdadul/miniconda3/envs/mlflow-9f5f4f3cda10ab2347ccce9b6c5c738f71f13546/lib/python3.10/site-packages/urllib3/connectionpool.py", line 449, in _make_request
    six.raise_from(e, None)
  File "<string>", line 3, in raise_from
  File "/home/imdadul/miniconda3/envs/mlflow-9f5f4f3cda10ab2347ccce9b6c5c738f71f13546/lib/python3.10/site-packages/urllib3/connectionpool.py", line 444, in _make_request
    httplib_response = conn.getresponse()
  File "/home/imdadul/miniconda3/envs/mlflow-9f5f4f3cda10ab2347ccce9b6c5c738f71f13546/lib/python3.10/http/client.py", line 1374, in getresponse
    response.begin()
  File "/home/imdadul/miniconda3/envs/mlflow-9f5f4f3cda10ab2347ccce9b6c5c738f71f13546/lib/python3.10/http/client.py", line 318, in begin
    version, status, reason = self._read_status()
  File "/home/imdadul/miniconda3/envs/mlflow-9f5f4f3cda10ab2347ccce9b6c5c738f71f13546/lib/python3.10/http/client.py", line 279, in _read_status
    line = str(self.fp.readline(_MAXLINE + 1), "iso-8859-1")
  File "/home/imdadul/miniconda3/envs/mlflow-9f5f4f3cda10ab2347ccce9b6c5c738f71f13546/lib/python3.10/socket.py", line 705, in readinto
    return self._sock.recv_into(b)
  File "/home/imdadul/miniconda3/envs/mlflow-9f5f4f3cda10ab2347ccce9b6c5c738f71f13546/lib/python3.10/ssl.py", line 1274, in recv_into
    return self.read(nbytes, buffer)
  File "/home/imdadul/miniconda3/envs/mlflow-9f5f4f3cda10ab2347ccce9b6c5c738f71f13546/lib/python3.10/ssl.py", line 1130, in read
    return self._sslobj.read(len, buffer)
TimeoutError: The read operation timed out

During handling of the above exception, another exception occurred:

Traceback (most recent call last):
  File "/home/imdadul/miniconda3/envs/mlflow-9f5f4f3cda10ab2347ccce9b6c5c738f71f13546/lib/python3.10/site-packages/requests/adapters.py", line 489, in send
    resp = conn.urlopen(
  File "/home/imdadul/miniconda3/envs/mlflow-9f5f4f3cda10ab2347ccce9b6c5c738f71f13546/lib/python3.10/site-packages/urllib3/connectionpool.py", line 785, in urlopen
    retries = retries.increment(
  File "/home/imdadul/miniconda3/envs/mlflow-9f5f4f3cda10ab2347ccce9b6c5c738f71f13546/lib/python3.10/site-packages/urllib3/util/retry.py", line 550, in increment
    raise six.reraise(type(error), error, _stacktrace)
  File "/home/imdadul/miniconda3/envs/mlflow-9f5f4f3cda10ab2347ccce9b6c5c738f71f13546/lib/python3.10/site-packages/urllib3/packages/six.py", line 770, in reraise
    raise value
  File "/home/imdadul/miniconda3/envs/mlflow-9f5f4f3cda10ab2347ccce9b6c5c738f71f13546/lib/python3.10/site-packages/urllib3/connectionpool.py", line 703, in urlopen
    httplib_response = self._make_request(
  File "/home/imdadul/miniconda3/envs/mlflow-9f5f4f3cda10ab2347ccce9b6c5c738f71f13546/lib/python3.10/site-packages/urllib3/connectionpool.py", line 451, in _make_request
    self._raise_timeout(err=e, url=url, timeout_value=read_timeout)
  File "/home/imdadul/miniconda3/envs/mlflow-9f5f4f3cda10ab2347ccce9b6c5c738f71f13546/lib/python3.10/site-packages/urllib3/connectionpool.py", line 340, in _raise_timeout
    raise ReadTimeoutError(
urllib3.exceptions.ReadTimeoutError: HTTPSConnectionPool(host='api.wandb.ai', port=443): Read timed out. (read timeout=10)

During handling of the above exception, another exception occurred:

Traceback (most recent call last):
  File "/home/imdadul/miniconda3/envs/mlflow-9f5f4f3cda10ab2347ccce9b6c5c738f71f13546/lib/python3.10/site-packages/wandb/sdk/lib/retry.py", line 102, in __call__
    result = self._call_fn(*args, **kwargs)
  File "/home/imdadul/miniconda3/envs/mlflow-9f5f4f3cda10ab2347ccce9b6c5c738f71f13546/lib/python3.10/site-packages/wandb/sdk/internal/internal_api.py", line 140, in execute
    return self.client.execute(*args, **kwargs)
  File "/home/imdadul/miniconda3/envs/mlflow-9f5f4f3cda10ab2347ccce9b6c5c738f71f13546/lib/python3.10/site-packages/wandb/vendor/gql-0.2.0/wandb_gql/client.py", line 52, in execute
    result = self._get_result(document, *args, **kwargs)
  File "/home/imdadul/miniconda3/envs/mlflow-9f5f4f3cda10ab2347ccce9b6c5c738f71f13546/lib/python3.10/site-packages/wandb/vendor/gql-0.2.0/wandb_gql/client.py", line 60, in _get_result
    return self.transport.execute(document, *args, **kwargs)
  File "/home/imdadul/miniconda3/envs/mlflow-9f5f4f3cda10ab2347ccce9b6c5c738f71f13546/lib/python3.10/site-packages/wandb/vendor/gql-0.2.0/wandb_gql/transport/requests.py", line 38, in execute
    request = requests.post(self.url, **post_args)
  File "/home/imdadul/miniconda3/envs/mlflow-9f5f4f3cda10ab2347ccce9b6c5c738f71f13546/lib/python3.10/site-packages/requests/api.py", line 115, in post
    return request("post", url, data=data, json=json, **kwargs)
  File "/home/imdadul/miniconda3/envs/mlflow-9f5f4f3cda10ab2347ccce9b6c5c738f71f13546/lib/python3.10/site-packages/requests/api.py", line 59, in request
    return session.request(method=method, url=url, **kwargs)
  File "/home/imdadul/miniconda3/envs/mlflow-9f5f4f3cda10ab2347ccce9b6c5c738f71f13546/lib/python3.10/site-packages/requests/sessions.py", line 587, in request
    resp = self.send(prep, **send_kwargs)
  File "/home/imdadul/miniconda3/envs/mlflow-9f5f4f3cda10ab2347ccce9b6c5c738f71f13546/lib/python3.10/site-packages/requests/sessions.py", line 701, in send
    r = adapter.send(request, **kwargs)
  File "/home/imdadul/miniconda3/envs/mlflow-9f5f4f3cda10ab2347ccce9b6c5c738f71f13546/lib/python3.10/site-packages/requests/adapters.py", line 578, in send
    raise ReadTimeout(e, request=request)
requests.exceptions.ReadTimeout: HTTPSConnectionPool(host='api.wandb.ai', port=443): Read timed out. (read timeout=10)
2022-07-04 14:02:07,801 ERROR   SenderThread:413719 [internal_api.py:execute():143] 409 response executing GraphQL.
2022-07-04 14:02:07,802 ERROR   SenderThread:413719 [internal_api.py:execute():144] {"errors":[{"message":"Error 1062: Duplicate entry '1100542-3p5zra5f' for key 'PRIMARY'","path":["upsertBucket"]}],"data":{"upsertBucket":null}}
2022-07-04 14:02:07,803 ERROR   MainThread:413719 [internal.py:wandb_internal():165] Thread SenderThread:
Traceback (most recent call last):
  File "/home/imdadul/miniconda3/envs/mlflow-9f5f4f3cda10ab2347ccce9b6c5c738f71f13546/lib/python3.10/site-packages/wandb/apis/normalize.py", line 22, in wrapper
    return func(*args, **kwargs)
  File "/home/imdadul/miniconda3/envs/mlflow-9f5f4f3cda10ab2347ccce9b6c5c738f71f13546/lib/python3.10/site-packages/wandb/sdk/internal/internal_api.py", line 1319, in upsert_run
    response = self.gql(mutation, variable_values=variable_values, **kwargs)
  File "/home/imdadul/miniconda3/envs/mlflow-9f5f4f3cda10ab2347ccce9b6c5c738f71f13546/lib/python3.10/site-packages/wandb/sdk/lib/retry.py", line 102, in __call__
    result = self._call_fn(*args, **kwargs)
  File "/home/imdadul/miniconda3/envs/mlflow-9f5f4f3cda10ab2347ccce9b6c5c738f71f13546/lib/python3.10/site-packages/wandb/sdk/internal/internal_api.py", line 140, in execute
    return self.client.execute(*args, **kwargs)
  File "/home/imdadul/miniconda3/envs/mlflow-9f5f4f3cda10ab2347ccce9b6c5c738f71f13546/lib/python3.10/site-packages/wandb/vendor/gql-0.2.0/wandb_gql/client.py", line 52, in execute
    result = self._get_result(document, *args, **kwargs)
  File "/home/imdadul/miniconda3/envs/mlflow-9f5f4f3cda10ab2347ccce9b6c5c738f71f13546/lib/python3.10/site-packages/wandb/vendor/gql-0.2.0/wandb_gql/client.py", line 60, in _get_result
    return self.transport.execute(document, *args, **kwargs)
  File "/home/imdadul/miniconda3/envs/mlflow-9f5f4f3cda10ab2347ccce9b6c5c738f71f13546/lib/python3.10/site-packages/wandb/vendor/gql-0.2.0/wandb_gql/transport/requests.py", line 39, in execute
    request.raise_for_status()
  File "/home/imdadul/miniconda3/envs/mlflow-9f5f4f3cda10ab2347ccce9b6c5c738f71f13546/lib/python3.10/site-packages/requests/models.py", line 1022, in raise_for_status
    raise HTTPError(http_error_msg, response=self)
requests.exceptions.HTTPError: 409 Client Error: Conflict for url: https://api.wandb.ai/graphql

During handling of the above exception, another exception occurred:

Traceback (most recent call last):
  File "/home/imdadul/miniconda3/envs/mlflow-9f5f4f3cda10ab2347ccce9b6c5c738f71f13546/lib/python3.10/site-packages/wandb/sdk/internal/internal_util.py", line 51, in run
    self._run()
  File "/home/imdadul/miniconda3/envs/mlflow-9f5f4f3cda10ab2347ccce9b6c5c738f71f13546/lib/python3.10/site-packages/wandb/sdk/internal/internal_util.py", line 102, in _run
    self._process(record)
  File "/home/imdadul/miniconda3/envs/mlflow-9f5f4f3cda10ab2347ccce9b6c5c738f71f13546/lib/python3.10/site-packages/wandb/sdk/internal/internal.py", line 310, in _process
    self._sm.send(record)
  File "/home/imdadul/miniconda3/envs/mlflow-9f5f4f3cda10ab2347ccce9b6c5c738f71f13546/lib/python3.10/site-packages/wandb/sdk/internal/sender.py", line 237, in send
    send_handler(record)
  File "/home/imdadul/miniconda3/envs/mlflow-9f5f4f3cda10ab2347ccce9b6c5c738f71f13546/lib/python3.10/site-packages/wandb/sdk/internal/sender.py", line 695, in send_run
    self._init_run(run, config_value_dict)
  File "/home/imdadul/miniconda3/envs/mlflow-9f5f4f3cda10ab2347ccce9b6c5c738f71f13546/lib/python3.10/site-packages/wandb/sdk/internal/sender.py", line 719, in _init_run
    server_run, inserted = self._api.upsert_run(
  File "/home/imdadul/miniconda3/envs/mlflow-9f5f4f3cda10ab2347ccce9b6c5c738f71f13546/lib/python3.10/site-packages/wandb/apis/normalize.py", line 24, in wrapper
    raise CommError(err.response, err)
wandb.errors.CommError: <Response [409]>
2022-07-04 14:02:09,817 INFO    MainThread:413719 [internal.py:handle_exit():80] Internal process exited
