2022-07-05 09:57:35,430 Fething artifact clean_census.csv:latest
2022-07-05 09:57:36,905 Splitting trainval and test
Traceback (most recent call last):
  File "/home/imdadul/miniconda3/envs/mlflow-89939b1aa50a2d5fcd882e362a07119fbc9acdd2/lib/python3.10/site-packages/pandas/core/indexes/base.py", line 3621, in get_loc
    return self._engine.get_loc(casted_key)
  File "pandas/_libs/index.pyx", line 136, in pandas._libs.index.IndexEngine.get_loc
  File "pandas/_libs/index.pyx", line 163, in pandas._libs.index.IndexEngine.get_loc
  File "pandas/_libs/hashtable_class_helper.pxi", line 5198, in pandas._libs.hashtable.PyObjectHashTable.get_item
  File "pandas/_libs/hashtable_class_helper.pxi", line 5206, in pandas._libs.hashtable.PyObjectHashTable.get_item
KeyError: 'neighbourhood_group'
The above exception was the direct cause of the following exception:
Traceback (most recent call last):
  File "/home/imdadul/Project Folder/Deploying a Machine Learning Model on Heroku with FastAPI/src/train_val_test_split/run.py", line 110, in <module>
    go(args)
  File "/home/imdadul/Project Folder/Deploying a Machine Learning Model on Heroku with FastAPI/src/train_val_test_split/run.py", line 62, in go
    stratify_by=df[args.stratify_by] if args.stratify_by != 'none' else None,
  File "/home/imdadul/miniconda3/envs/mlflow-89939b1aa50a2d5fcd882e362a07119fbc9acdd2/lib/python3.10/site-packages/pandas/core/frame.py", line 3505, in __getitem__
    indexer = self.columns.get_loc(key)
  File "/home/imdadul/miniconda3/envs/mlflow-89939b1aa50a2d5fcd882e362a07119fbc9acdd2/lib/python3.10/site-packages/pandas/core/indexes/base.py", line 3623, in get_loc
    raise KeyError(key) from err
KeyError: 'neighbourhood_group'