2022-07-05 11:16:34,658 Preparing sklearn pipeline
2022-07-05 11:16:34,659 Fitting
Traceback (most recent call last):
  File "/home/imdadul/miniconda3/envs/mlflow-0de342770e7ce12176a4dd86c6d72609da6e87bd/lib/python3.10/site-packages/pandas/core/indexes/base.py", line 3621, in get_loc
    return self._engine.get_loc(casted_key)
  File "pandas/_libs/index.pyx", line 136, in pandas._libs.index.IndexEngine.get_loc
  File "pandas/_libs/index.pyx", line 163, in pandas._libs.index.IndexEngine.get_loc
  File "pandas/_libs/hashtable_class_helper.pxi", line 5198, in pandas._libs.hashtable.PyObjectHashTable.get_item
  File "pandas/_libs/hashtable_class_helper.pxi", line 5206, in pandas._libs.hashtable.PyObjectHashTable.get_item
KeyError: 'fnlwgt'
The above exception was the direct cause of the following exception:
Traceback (most recent call last):
  File "/home/imdadul/miniconda3/envs/mlflow-0de342770e7ce12176a4dd86c6d72609da6e87bd/lib/python3.10/site-packages/sklearn/utils/__init__.py", line 416, in _get_column_indices
    col_idx = all_columns.get_loc(col)
  File "/home/imdadul/miniconda3/envs/mlflow-0de342770e7ce12176a4dd86c6d72609da6e87bd/lib/python3.10/site-packages/pandas/core/indexes/base.py", line 3623, in get_loc
    raise KeyError(key) from err
KeyError: 'fnlwgt'
The above exception was the direct cause of the following exception:
Traceback (most recent call last):
  File "/home/imdadul/Project Folder/Deploying a Machine Learning Model on Heroku with FastAPI/src/train_random_forest/run.py", line 246, in <module>
    go(args)
  File "/home/imdadul/Project Folder/Deploying a Machine Learning Model on Heroku with FastAPI/src/train_random_forest/run.py", line 70, in go
    sk_pipe.fit(X_train, y_train)
  File "/home/imdadul/miniconda3/envs/mlflow-0de342770e7ce12176a4dd86c6d72609da6e87bd/lib/python3.10/site-packages/sklearn/pipeline.py", line 378, in fit
    Xt = self._fit(X, y, **fit_params_steps)
  File "/home/imdadul/miniconda3/envs/mlflow-0de342770e7ce12176a4dd86c6d72609da6e87bd/lib/python3.10/site-packages/sklearn/pipeline.py", line 336, in _fit
    X, fitted_transformer = fit_transform_one_cached(
  File "/home/imdadul/miniconda3/envs/mlflow-0de342770e7ce12176a4dd86c6d72609da6e87bd/lib/python3.10/site-packages/joblib/memory.py", line 349, in __call__
    return self.func(*args, **kwargs)
  File "/home/imdadul/miniconda3/envs/mlflow-0de342770e7ce12176a4dd86c6d72609da6e87bd/lib/python3.10/site-packages/sklearn/pipeline.py", line 870, in _fit_transform_one
    res = transformer.fit_transform(X, y, **fit_params)
  File "/home/imdadul/miniconda3/envs/mlflow-0de342770e7ce12176a4dd86c6d72609da6e87bd/lib/python3.10/site-packages/sklearn/compose/_column_transformer.py", line 670, in fit_transform
    self._validate_column_callables(X)
  File "/home/imdadul/miniconda3/envs/mlflow-0de342770e7ce12176a4dd86c6d72609da6e87bd/lib/python3.10/site-packages/sklearn/compose/_column_transformer.py", line 357, in _validate_column_callables
    transformer_to_input_indices[name] = _get_column_indices(X, columns)
  File "/home/imdadul/miniconda3/envs/mlflow-0de342770e7ce12176a4dd86c6d72609da6e87bd/lib/python3.10/site-packages/sklearn/utils/__init__.py", line 424, in _get_column_indices
    raise ValueError("A given column is not a column of the dataframe") from e
ValueError: A given column is not a column of the dataframe