Traceback (most recent call last):
  File "/home/imdadul/miniconda3/envs/mlflow-0de342770e7ce12176a4dd86c6d72609da6e87bd/lib/python3.10/site-packages/pandas/core/indexes/base.py", line 3621, in get_loc
    return self._engine.get_loc(casted_key)
  File "pandas/_libs/index.pyx", line 136, in pandas._libs.index.IndexEngine.get_loc
  File "pandas/_libs/index.pyx", line 163, in pandas._libs.index.IndexEngine.get_loc
  File "pandas/_libs/hashtable_class_helper.pxi", line 5198, in pandas._libs.hashtable.PyObjectHashTable.get_item
  File "pandas/_libs/hashtable_class_helper.pxi", line 5206, in pandas._libs.hashtable.PyObjectHashTable.get_item
KeyError: 'none'
The above exception was the direct cause of the following exception:
Traceback (most recent call last):
  File "/home/imdadul/Project Folder/Deploying a Machine Learning Model on Heroku with FastAPI/src/train_random_forest/run.py", line 242, in <module>
    go(args)
  File "/home/imdadul/Project Folder/Deploying a Machine Learning Model on Heroku with FastAPI/src/train_random_forest/run.py", line 53, in go
    X, y, test_size=args.val_size, stratify=X[args.stratify_by], random_state=args.random_seed
  File "/home/imdadul/miniconda3/envs/mlflow-0de342770e7ce12176a4dd86c6d72609da6e87bd/lib/python3.10/site-packages/pandas/core/frame.py", line 3505, in __getitem__
    indexer = self.columns.get_loc(key)
  File "/home/imdadul/miniconda3/envs/mlflow-0de342770e7ce12176a4dd86c6d72609da6e87bd/lib/python3.10/site-packages/pandas/core/indexes/base.py", line 3623, in get_loc
    raise KeyError(key) from err
KeyError: 'none'